Workbook

Sheet Raw Material
B2: Raw Material Prices | H2: ='[1]Raw Material'!$J$4 -> 46114
B4: U$/Egp | C4: ='[1]Raw Material'!C4 -> 55 | F4: Import charges % | G4: ='[1]Raw Material'!F4 -> 0.07
B5: Euro/$ | C5: ='[1]Raw Material'!C5 -> 1.16 | F5: Customs | G5: ='[1]Raw Material'!F5 -> 0.05
B7: Kind | C7: CODE | D7: R.M. Type | E7: R.M. Name | F7: R.M. Grades | G7: Currency | H7: Warehouse Material Cost | I7: Warehouse Material Qty | J7: On the Way Material Cost | K7: On the Way Material Qty | L7: Price List Material Cost | M7: Average Material Cost | N7: Average Material Qty
B9: ='[1]Raw Material'!B8 -> Raw Material | D9: ='[1]Raw Material'!C8 -> PE | E9: ='[1]Raw Material'!D8 -> LDPE | F9: ='[1]Raw Material'!E8 -> 0 | H9: 2145.35
B10: ='[1]Raw Material'!B9 -> Raw Material | D10: ='[1]Raw Material'!C9 -> PE | E10: ='[1]Raw Material'!D9 -> LLDPE | F10: ='[1]Raw Material'!E9 -> 0 | H10: 1904.6
B11: ='[1]Raw Material'!B10 -> Raw Material | D11: ='[1]Raw Material'!C10 -> PE | E11: ='[1]Raw Material'!D10 -> LLDPE 6201 | F11: ='[1]Raw Material'!E10 -> 0 | H11: 1904.6
B12: ='[1]Raw Material'!B11 -> Raw Material | D12: ='[1]Raw Material'!C11 -> PE | E12: ='[1]Raw Material'!D11 -> HDPE | F12: ='[1]Raw Material'!E11 -> 0 | H12: 1952.75
B13: ='[1]Raw Material'!B12 -> Raw Material | D13: ='[1]Raw Material'!C12 -> PE | E13: ='[1]Raw Material'!D12 -> HDPE HTA108 | F13: ='[1]Raw Material'!E12 -> 0 | H13: 1974.15
B14: ='[1]Raw Material'!B13 -> Raw Material | D14: ='[1]Raw Material'!C13 -> PE | E14: ='[1]Raw Material'!D13 -> MDPE | F14: ='[1]Raw Material'!E13 -> 0 | H14: 2006.25
B15: ='[1]Raw Material'!B14 -> Raw Material | D15: ='[1]Raw Material'!C14 -> PE | E15: ='[1]Raw Material'!D14 -> Enable | F15: ='[1]Raw Material'!E14 -> 0 | H15: 1979.5
B16: ='[1]Raw Material'!B15 -> Raw Material | D16: ='[1]Raw Material'!C15 -> PE | E16: ='[1]Raw Material'!D15 -> Enable 3305 | F16: ='[1]Raw Material'!E15 -> 0 | H16: 1979.5
B17: ='[1]Raw Material'!B16 -> Raw Material | D17: ='[1]Raw Material'!C16 -> PE | E17: ='[1]Raw Material'!D16 -> MDPE K307 | F17: ='[1]Raw Material'!E16 -> 0 | H17: 2113.25
B18: ='[1]Raw Material'!B17 -> Raw Material | D18: ='[1]Raw Material'!C17 -> PE | E18: ='[1]Raw Material'!D17 -> Exceed | F18: ='[1]Raw Material'!E17 -> 0 | H18: 2000.9
B19: ='[1]Raw Material'!B18 -> Raw Material | D19: ='[1]Raw Material'!C18 -> PE | E19: ='[1]Raw Material'!D18 -> Exceed XP | F19: ='[1]Raw Material'!E18 -> 0 | H19: 2123.95
B20: ='[1]Raw Material'!B19 -> Raw Material | D20: ='[1]Raw Material'!C19 -> PE | E20: ='[1]Raw Material'!D19 -> Exceed XP7 | F20: ='[1]Raw Material'!E19 -> 0 | H20: 2166.75
... B24: ='[1]Raw Material'!B23 -> Raw Material | D24: ='[1]Raw Material'!C23 -> EVA | E24: ='[1]Raw Material'!D23 -> EVA | F24: ='[1]Raw Material'!E23 -> 0 | H24: 2557.3
B25: ='[1]Raw Material'!B31 -> Raw Material | D25: ='[1]Raw Material'!C31 -> Copolymer | E25: ='[1]Raw Material'!D31 -> Vistamax | F25: ='[1]Raw Material'!E31 -> 0 | H25: 3477.5
B26: ='[1]Raw Material'!B32 -> Raw Material | D26: ='[1]Raw Material'!C32 -> Filler | E26: ='[1]Raw Material'!D32 -> Filler | F26: ='[1]Raw Material'!E32 -> 0 | H26: 509.09091
B27: ='[1]Raw Material'!B33 -> Raw Material | D27: ='[1]Raw Material'!C33 -> G2 | E27: ='[1]Raw Material'!D33 -> G2 Transparent 80% | F27: ='[1]Raw Material'!E33 -> 0 | H27: 1619.98
B28: ='[1]Raw Material'!B34 -> Raw Material | D28: ='[1]Raw Material'!C34 -> G2 | E28: ='[1]Raw Material'!D34 -> Indoor G2 65% | F28: ='[1]Raw Material'!E34 -> 0 | H28: 1417.4825
B29: ='[1]Raw Material'!B35 -> Raw Material | D29: ='[1]Raw Material'!C35 -> G2 | E29: ='[1]Raw Material'!D35 -> PIR | F29: ='[1]Raw Material'!E35 -> 0 | H29: 1417.4825
B30: ='[1]Raw Material'!B36 -> Raw Material | D30: ='[1]Raw Material'!C36 -> G2 | E30: ='[1]Raw Material'!D36 -> PCR | F30: ='[1]Raw Material'!E36 -> 0 | H30: 818.18182
B31: ='[1]Raw Material'!B37 -> Raw Material | D31: ='[1]Raw Material'!C37 -> G2 | E31: ='[1]Raw Material'!D37 -> Agriculture G2 80% | F31: ='[1]Raw Material'!E37 -> 0 | H31: 1822.4775
B32: ='[1]Raw Material'!B45 -> Master Batch | D32: ='[1]Raw Material'!C45 -> Color M.B. | E32: ='[1]Raw Material'!D45 -> Black M.B. SRF 50% | F32: ='[1]Raw Material'!E45 -> 0 | H32: 0
B33: ='[1]Raw Material'!B46 -> Master Batch | D33: ='[1]Raw Material'!C46 -> Color M.B. | E33: ='[1]Raw Material'!D46 -> Black M.B. SRF 60% | F33: ='[1]Raw Material'!E46 -> 0 | H33: 3103
B34: ='[1]Raw Material'!B47 -> Master Batch | D34: ='[1]Raw Material'!C47 -> Color M.B. | E34: ='[1]Raw Material'!D47 -> Black M.B. 40% PType | F34: ='[1]Raw Material'!E47 -> 0 | H34: 2978.88
B35: ='[1]Raw Material'!B48 -> Master Batch | D35: ='[1]Raw Material'!C48 -> Color M.B. | E35: ='[1]Raw Material'!D48 -> Black M.B. 50% PType | F35: ='[1]Raw Material'!E48 -> 0 | H35: 3227.12
B36: ='[1]Raw Material'!B49 -> Master Batch | D36: ='[1]Raw Material'!C49 -> Color M.B. | E36: ='[1]Raw Material'!D49 -> White M.B. | F36: ='[1]Raw Material'!E49 -> 0 | H36: 3181.8182
B37: ='[1]Raw Material'!B50 -> Master Batch | D37: ='[1]Raw Material'!C50 -> Color M.B. | E37: ='[1]Raw Material'!D50 -> Blue M.B. | F37: ='[1]Raw Material'!E50 -> 0 | H37: 3272.7273
B38: ='[1]Raw Material'!B51 -> Master Batch | D38: ='[1]Raw Material'!C51 -> Color M.B. | E38: ='[1]Raw Material'!D51 -> Silver M.B. | F38: ='[1]Raw Material'!E51 -> 0 | H38: 3636.3636
B39: ='[1]Raw Material'!B52 -> Master Batch | D39: ='[1]Raw Material'!C52 -> Color M.B. | E39: ='[1]Raw Material'!D52 -> Red M.B. | F39: ='[1]Raw Material'!E52 -> 0 | H39: 3636.3636
B40: ='[1]Raw Material'!B53 -> Master Batch | D40: ='[1]Raw Material'!C53 -> Color M.B. | E40: ='[1]Raw Material'!D53 -> Green M.B. | F40: ='[1]Raw Material'!E53 -> 0 | H40: 3181.8182
B41: ='[1]Raw Material'!B54 -> Master Batch | D41: ='[1]Raw Material'!C54 -> Color M.B. | E41: ='[1]Raw Material'!D54 -> Brown M.B. | F41: ='[1]Raw Material'!E54 -> 0 | H41: 3272.7273
B42: ='[1]Raw Material'!B55 -> Master Batch | D42: ='[1]Raw Material'!C55 -> Color M.B. | E42: ='[1]Raw Material'!D55 -> Yellow M.B. | F42: ='[1]Raw Material'!E55 -> 0 | H42: 3818.1818
B43: ='[1]Raw Material'!B56 -> Master Batch | D43: ='[1]Raw Material'!C56 -> Additive M.B. | E43: ='[1]Raw Material'!D56 -> Processing Aid | F43: ='[1]Raw Material'!E56 -> PPA - 350 | H43: 3852
... B72: ='[1]Raw Material'!B85 -> Master Batch | D72: ='[1]Raw Material'!C85 -> Additive M.B. | E72: ='[1]Raw Material'!D85 -> IR Absorber | F72: ='[1]Raw Material'!E85 -> Second Sky | H72: 32100
B73: ='[1]Raw Material'!B101 -> Kind | D73: ='[1]Raw Material'!C101 -> Type | E73: ='[1]Raw Material'!D101 -> Raw Material Grade | F73: ='[1]Raw Material'!E101 -> 0 | H73: Cost Us$
B74: ='[1]Raw Material'!B102 -> Printing Material | D74: ='[1]Raw Material'!C102 -> Ink | E74: ='[1]Raw Material'!D102 -> Black Flexo | F74: ='[1]Raw Material'!E102 -> 0 | H74: 3272.7273
B75: ='[1]Raw Material'!B103 -> Printing Material | D75: ='[1]Raw Material'!C103 -> Ink | E75: ='[1]Raw Material'!D103 -> White Flexo | F75: ='[1]Raw Material'!E103 -> 0 | H75: 2945.4545
...

Sheet Recipe
B2: Product Recipe Report
B5: Product Name
B6: Product Code
B7: Customer
B8: Name | C8: Width | D8: Thickness | E8: Length | F8: Gusset | G8: Gusseted Size | H8: Film Color | I8: Printed | J8: Length
B9: Unit | C9: cm | D9: micon | E9: m | G9: cm | J9: cm
B10: Data
B12: Material No. | C12: Material Type | D12: Layer # | E12: 1 | F12: 2 | G12: 3 | H12: 4 | I12: 5 | J12: Total
D13: Layer Name | E13: A | F13: B | G13: C | H13: D | I13: E
D14: Layer % | J14: =SUM(E14:I14) -> 0
D15: Material Grade
B16: 1 | J16: =($E$14*E16)+($F$14*F16)+($G$14*G16)+($H$14*H16)+($I$14*I16) -> 0
B17: 2 | J17: =($E$14*E17)+($F$14*F17)+($G$14*G17)+($H$14*H17)+($I$14*I17) -> 0
B18: 3 | J18: =($E$14*E18)+($F$14*F18)+($G$14*G18)+($H$14*H18)+($I$14*I18) -> 0
B19: 4 | J19: =($E$14*E19)+($F$14*F19)+($G$14*G19)+($H$14*H19)+($I$14*I19) -> 0
B20: 5 | J20: =($E$14*E20)+($F$14*F20)+($G$14*G20)+($H$14*H20)+($I$14*I20) -> 0
B21: 6 | J21: =($E$14*E21)+($F$14*F21)+($G$14*G21)+($H$14*H21)+($I$14*I21) -> 0
B22: 7 | J22: =($E$14*E22)+($F$14*F22)+($G$14*G22)+($H$14*H22)+($I$14*I22) -> 0
B23: 8 | J23: =($E$14*E23)+($F$14*F23)+($G$14*G23)+($H$14*H23)+($I$14*I23) -> 0
B24: 9 | J24: =($E$14*E24)+($F$14*F24)+($G$14*G24)+($H$14*H24)+($I$14*I24) -> 0
B25: 10 | J25: =($E$14*E25)+($F$14*F25)+($G$14*G25)+($H$14*H25)+($I$14*I25) -> 0
B26: 11 | J26: =($E$14*E26)+($F$14*F26)+($G$14*G26)+($H$14*H26)+($I$14*I26) -> 0
B27: 12 | J27: =($E$14*E27)+($F$14*F27)+($G$14*G27)+($H$14*H27)+($I$14*I27) -> 0
... B30: 15 | J30: =($E$14*E30)+($F$14*F30)+($G$14*G30)+($H$14*H30)+($I$14*I30) -> 0
B31: Total | E31: =SUM(E16:E30) -> 0 | F31: =SUM(F16:F30) -> 0 | G31: =SUM(G16:G30) -> 0 | H31: =SUM(H16:H30) -> 0 | I31: =SUM(I16:I30) -> 0 | J31: =SUM(J16:J30) -> 0
B33: Printing Mat. | C33: Ink Type | D33: Name | E33: Kg/Ton | G33: Packaging Mat. | H33: Pack. Type | I33: Pack. Description | J33: Qty/Ton
B34: 1 | C34: Ink 1 | G34: 1
B35: 2 | C35: Ink 2 | G35: 2
B36: 3 | C36: Ink 3 | G36: 3
B37: 4 | C37: Ink 4 | G37: 4
B38: 5 | C38: Ink 5 | G38: 5
B39: 6 | C39: Ink 6 | G39: 6
B40: 7 | C40: Ink 7 | G40: 7
B41: 8 | C41: Ink 8 | G41: 8
B42: 9 | C42: Solvent | G42: 9
B43: 10 | C43: Solvent | G43: 10
B44: 11 | C44: Solvent | G44: 11
B45: 12 | C45: Ink Additive | G45: 12
B46: Total | E46: =SUM(E34:E45) -> 0 | G46: Total | J46: =SUM(J34:J45) -> 0
B48: Production & Machinability Data Data
...

Sheet Cost
B2: Product Recipe Report
C5: Raw material Type | D5: Raw material Grade | E5: Price/Ton | F5: Recipe | G5: % | H5: Price/Ton
C7: =Recipe!C16 -> 0 | D7: =Recipe!D16 -> 0 | E7: =IFERROR(VLOOKUP(C7,'Raw Material'!$E$9:$H$72,3,FALSE),0) -> 0 | F7: =G7*1000 -> 0 | G7: =Recipe!J16 -> 0 | H7: =IFERROR(G7*E7,0) -> 0
C8: =Recipe!C17 -> 0 | D8: =Recipe!D17 -> 0 | E8: =IFERROR(VLOOKUP(C8,'Raw Material'!$E$9:$H$72,3,FALSE),0) -> 0 | F8: =G8*1000 -> 0 | G8: =Recipe!J17 -> 0 | H8: =IFERROR(G8*E8,0) -> 0
C9: =Recipe!C18 -> 0 | D9: =Recipe!D18 -> 0 | E9: =IFERROR(VLOOKUP(C9,'Raw Material'!$E$9:$H$72,3,FALSE),0) -> 0 | F9: =G9*1000 -> 0 | G9: =Recipe!J18 -> 0 | H9: =IFERROR(G9*E9,0) -> 0
C10: =Recipe!C19 -> 0 | D10: =Recipe!D19 -> 0 | E10: =IFERROR(VLOOKUP(C10,'Raw Material'!$E$9:$H$72,3,FALSE),0) -> 0 | F10: =G10*1000 -> 0 | G10: =Recipe!J19 -> 0 | H10: =IFERROR(G10*E10,0) -> 0
C11: =Recipe!C20 -> 0 | D11: =Recipe!D20 -> 0 | E11: =IFERROR(VLOOKUP(C11,'Raw Material'!$E$9:$H$72,3,FALSE),0) -> 0 | F11: =G11*1000 -> 0 | G11: =Recipe!J20 -> 0 | H11: =IFERROR(G11*E11,0) -> 0
C12: =Recipe!C21 -> 0 | D12: =Recipe!D21 -> 0 | E12: =IFERROR(VLOOKUP(C12,'Raw Material'!$E$9:$H$72,3,FALSE),0) -> 0 | F12: =G12*1000 -> 0 | G12: =Recipe!J21 -> 0 | H12: =IFERROR(G12*E12,0) -> 0
C13: =Recipe!C22 -> 0 | D13: =Recipe!D22 -> 0 | E13: =IFERROR(VLOOKUP(C13,'Raw Material'!$E$9:$H$72,3,FALSE),0) -> 0 | F13: =G13*1000 -> 0 | G13: =Recipe!J22 -> 0 | H13: =IFERROR(G13*E13,0) -> 0
C14: =Recipe!C23 -> 0 | D14: =Recipe!D23 -> 0 | E14: =IFERROR(VLOOKUP(C14,'Raw Material'!$E$9:$H$72,3,FALSE),0) -> 0 | F14: =G14*1000 -> 0 | G14: =Recipe!J23 -> 0 | H14: =IFERROR(G14*E14,0) -> 0
C15: =Recipe!C24 -> 0 | D15: =Recipe!D24 -> 0 | E15: =IFERROR(VLOOKUP(C15,'Raw Material'!$E$9:$H$72,3,FALSE),0) -> 0 | F15: =G15*1000 -> 0 | G15: =Recipe!J24 -> 0 | H15: =IFERROR(G15*E15,0) -> 0
C16: =Recipe!C25 -> 0 | D16: =Recipe!D25 -> 0 | E16: =IFERROR(VLOOKUP(C16,'Raw Material'!$E$9:$H$72,3,FALSE),0) -> 0 | F16: =G16*1000 -> 0 | G16: =Recipe!J25 -> 0 | H16: =IFERROR(G16*E16,0) -> 0
C17: =Recipe!C26 -> 0 | D17: =Recipe!D26 -> 0 | E17: =IFERROR(VLOOKUP(C17,'Raw Material'!$E$9:$H$72,3,FALSE),0) -> 0 | F17: =G17*1000 -> 0 | G17: =Recipe!J26 -> 0 | H17: =IFERROR(G17*E17,0) -> 0
C18: =Recipe!C27 -> 0 | D18: =Recipe!D27 -> 0 | E18: =IFERROR(VLOOKUP(C18,'Raw Material'!$E$9:$H$72,3,FALSE),0) -> 0 | F18: =G18*1000 -> 0 | G18: =Recipe!J27 -> 0 | H18: =IFERROR(G18*E18,0) -> 0
... C20: =Recipe!C29 -> 0 | D20: =Recipe!D29 -> 0 | E20: =IFERROR(VLOOKUP(C20,'Raw Material'!$E$9:$H$72,3,FALSE),0) -> 0 | F20: =G20*1000 -> 0 | G20: =Recipe!J29 -> 0 | H20: =IFERROR(G20*E20,0) -> 0
C21: Total Raw Material Cost | F21: =SUM(F7:F20) -> 0 | G21: =SUM(G7:G20) -> 0 | H21: =SUM(H7:H20) -> 0
C23: Printing material Type | D23: Printing material Grade | E23: Price/Ton | F23: Consumption kg /Ton | G23: % of total | H23: Cost in Ton
C25: =Recipe!C34 -> Ink 1 | D25: =Recipe!D34 -> 0 | E25: =IFERROR(VLOOKUP(D25,'Raw Material'!$E$9:$H$72,3,FALSE),0) -> 0 | F25: =Recipe!E34 -> 0 | G25: =IFERROR(F25/$F$65,0) -> 0 | H25: =E25/1000*F25 -> 0
C26: =Recipe!C35 -> Ink 2 | D26: =Recipe!D35 -> 0 | E26: =IFERROR(VLOOKUP(D26,'Raw Material'!$E$9:$H$72,3,FALSE),0) -> 0 | F26: =Recipe!E35 -> 0 | G26: =IFERROR(F26/$F$65,0) -> 0 | H26: =E26/1000*F26 -> 0
C27: =Recipe!C36 -> Ink 3 | D27: =Recipe!D36 -> 0 | E27: =IFERROR(VLOOKUP(D27,'Raw Material'!$E$9:$H$72,3,FALSE),0) -> 0 | F27: =Recipe!E36 -> 0 | G27: =IFERROR(F27/$F$65,0) -> 0 | H27: =E27/1000*F27 -> 0
C28: =Recipe!C37 -> Ink 4 | D28: =Recipe!D37 -> 0 | E28: =IFERROR(VLOOKUP(D28,'Raw Material'!$E$9:$H$72,3,FALSE),0) -> 0 | F28: =Recipe!E37 -> 0 | G28: =IFERROR(F28/$F$65,0) -> 0 | H28: =E28/1000*F28 -> 0
C29: =Recipe!C38 -> Ink 5 | D29: =Recipe!D38 -> 0 | E29: =IFERROR(VLOOKUP(D29,'Raw Material'!$E$9:$H$72,3,FALSE),0) -> 0 | F29: =Recipe!E38 -> 0 | G29: =IFERROR(F29/$F$65,0) -> 0 | H29: =E29/1000*F29 -> 0
C30: =Recipe!C39 -> Ink 6 | D30: =Recipe!D39 -> 0 | E30: =IFERROR(VLOOKUP(D30,'Raw Material'!$E$9:$H$72,3,FALSE),0) -> 0 | F30: =Recipe!E39 -> 0 | G30: =IFERROR(F30/$F$65,0) -> 0 | H30: =E30/1000*F30 -> 0
C31: =Recipe!C40 -> Ink 7 | D31: =Recipe!D40 -> 0 | E31: =IFERROR(VLOOKUP(D31,'Raw Material'!$E$9:$H$72,3,FALSE),0) -> 0 | F31: =Recipe!E40 -> 0 | G31: =IFERROR(F31/$F$65,0) -> 0 | H31: =E31/1000*F31 -> 0
C32: =Recipe!C41 -> Ink 8 | D32: =Recipe!D41 -> 0 | E32: =IFERROR(VLOOKUP(D32,'Raw Material'!$E$9:$H$72,3,FALSE),0) -> 0 | F32: =Recipe!E41 -> 0 | G32: =IFERROR(F32/$F$65,0) -> 0 | H32: =E32/1000*F32 -> 0
C33: =Recipe!C42 -> Solvent | D33: =Recipe!D42 -> 0 | E33: =IFERROR(VLOOKUP(D33,'Raw Material'!$E$9:$H$72,3,FALSE),0) -> 0 | F33: =Recipe!E42 -> 0 | G33: =IFERROR(F33/$F$65,0) -> 0 | H33: =E33/1000*F33 -> 0
C34: =Recipe!C43 -> Solvent | D34: =Recipe!D43 -> 0 | E34: =IFERROR(VLOOKUP(D34,'Raw Material'!$E$9:$H$72,3,FALSE),0) -> 0 | F34: =Recipe!E43 -> 0 | G34: =IFERROR(F34/$F$65,0) -> 0 | H34: =E34/1000*F34 -> 0
C35: =Recipe!C44 -> Solvent | D35: =Recipe!D44 -> 0 | E35: =IFERROR(VLOOKUP(D35,'Raw Material'!$E$9:$H$72,3,FALSE),0) -> 0 | F35: =Recipe!E44 -> 0 | G35: =IFERROR(F35/$F$65,0) -> 0 | H35: =E35/1000*F35 -> 0
C36: =Recipe!C45 -> Ink Additive | D36: =Recipe!D45 -> 0 | E36: =IFERROR(VLOOKUP(D36,'Raw Material'!$E$9:$H$72,3,FALSE),0) -> 0 | F36: =Recipe!E45 -> 0 | G36: =IFERROR(F36/$F$65,0) -> 0 | H36: =E36/1000*F36 -> 0
C37: Total Printing Material Cost | F37: =SUM(F25:F36) -> 0 | G37: =SUM(G25:G36) -> 0 | H37: =SUM(H25:H36) -> 0
C39: Packaging Type | D39: Packaging Details | E39: Price/unit | F39: Consumption / Ton | H39: Cost in Ton
C41: =Recipe!H34 -> 0 | D41: =Recipe!I34 -> 0 | E41: =IFERROR(VLOOKUP(D41,'Raw Material'!$E$9:$H$151,3,FALSE),0) -> 0 | F41: =Recipe!J34 -> 0 | H41: =F41*E41 -> 0
C42: =Recipe!H35 -> 0 | D42: =Recipe!I35 -> 0 | E42: =IFERROR(VLOOKUP(D42,'Raw Material'!$E$9:$H$151,3,FALSE),0) -> 0 | F42: =Recipe!J35 -> 0 | H42: =F42*E42 -> 0
C43: =Recipe!H36 -> 0 | D43: =Recipe!I36 -> 0 | E43: =IFERROR(VLOOKUP(D43,'Raw Material'!$E$9:$H$151,3,FALSE),0) -> 0 | F43: =Recipe!J36 -> 0 | H43: =F43*E43 -> 0
C44: =Recipe!H37 -> 0 | D44: =Recipe!I37 -> 0 | E44: =IFERROR(VLOOKUP(D44,'Raw Material'!$E$9:$H$151,3,FALSE),0) -> 0 | F44: =Recipe!J37 -> 0 | H44: =F44*E44 -> 0
C45: =Recipe!H38 -> 0 | D45: =Recipe!I38 -> 0 | E45: =IFERROR(VLOOKUP(D45,'Raw Material'!$E$9:$H$151,3,FALSE),0) -> 0 | F45: =Recipe!J38 -> 0 | H45: =F45*E45 -> 0
C46: =Recipe!H39 -> 0 | D46: =Recipe!I39 -> 0 | E46: =IFERROR(VLOOKUP(D46,'Raw Material'!$E$9:$H$151,3,FALSE),0) -> 0 | F46: =Recipe!J39 -> 0 | H46: =F46*E46 -> 0
C47: =Recipe!H40 -> 0 | D47: =Recipe!I40 -> 0 | E47: =IFERROR(VLOOKUP(D47,'Raw Material'!$E$9:$H$151,3,FALSE),0) -> 0 | F47: =Recipe!J40 -> 0 | H47: =F47*E47 -> 0
C48: =Recipe!H41 -> 0 | D48: =Recipe!I41 -> 0 | E48: =IFERROR(VLOOKUP(D48,'Raw Material'!$E$9:$H$151,3,FALSE),0) -> 0 | F48: =Recipe!J41 -> 0 | H48: =F48*E48 -> 0
C49: =Recipe!H42 -> 0 | D49: =Recipe!I42 -> 0 | E49: =IFERROR(VLOOKUP(D49,'Raw Material'!$E$9:$H$151,3,FALSE),0) -> 0 | F49: =Recipe!J42 -> 0 | H49: =F49*E49 -> 0
...
